Workbook
Name UPDATE: #REF!

Sheet Profit & Loss
A1: ='Data Sheet'!B1 -> TATA STEEL LTD | M1: SCREENER.IN
A3: Narration | B3: ='Data Sheet'!B16 -> 42825 | C3: ='Data Sheet'!C16 -> 43190 | D3: ='Data Sheet'!D16 -> 43555 | E3: ='Data Sheet'!E16 -> 43921 | F3: ='Data Sheet'!F16 -> 44286 | G3: ='Data Sheet'!G16 -> 44651 | H3: ='Data Sheet'!H16 -> 45016 | I3: ='Data Sheet'!I16 -> 45382 | ... K3: ='Data Sheet'!K16 -> 46112 | L3: Trailing | M3: Best Case | N3: Worst Case
A4: Sales | B4: ='Data Sheet'!B17 -> 112299.42 | C4: ='Data Sheet'!C17 -> 123249.07 | D4: ='Data Sheet'!D17 -> 157668.99 | E4: ='Data Sheet'!E17 -> 139816.65 | F4: ='Data Sheet'!F17 -> 156477.4 | G4: ='Data Sheet'!G17 -> 243959.17 | H4: ='Data Sheet'!H17 -> 243352.69 | I4: ='Data Sheet'!I17 -> 229170.78 | ... K4: ='Data Sheet'!K17 -> 232139.94 | L4: =SUM(Quarters!H4:K4) -> 232139.94 | M4: =$K4+M23*K4 -> 246583.38 | N4: =$K4+N23*L4 -> 228518.36
A5: Expenses | B5: =SUM('Data Sheet'!B18,'Data Sheet'!B20:B24, -1*'Data Sheet'!B19) -> 99155.79 | C5: =SUM('Data Sheet'!C18,'Data Sheet'!C20:C24, -1*'Data Sheet'!C19) -> 101815.88 | D5: =SUM('Data Sheet'!D18,'Data Sheet'!D20:D24, -1*'Data Sheet'!D19) -> 128350.77 | E5: =SUM('Data Sheet'!E18,'Data Sheet'!E20:E24, -1*'Data Sheet'!E19) -> 122353.59 | F5: =SUM('Data Sheet'!F18,'Data Sheet'!F20:F24, -1*'Data Sheet'!F19) -> 125973.14 | G5: =SUM('Data Sheet'!G18,'Data Sheet'!G20:G24, -1*'Data Sheet'!G19) -> 180469.22 | H5: =SUM('Data Sheet'!H18,'Data Sheet'!H20:H24, -1*'Data Sheet'!H19) -> 211052.53 | I5: =SUM('Data Sheet'!I18,'Data Sheet'!I20:I24, -1*'Data Sheet'!I19) -> 206922.86 | ... K5: =SUM('Data Sheet'!K18,'Data Sheet'!K20:K24, -1*'Data Sheet'!K19) -> 197787.5 | L5: =SUM(Quarters!H5:K5) -> 197787.5 | M5: =M4-M6 -> 210093.58 | N5: =N4-N6 -> 200989.8
A6: Operating Profit | B6: =B4-B5 -> 13143.63 | C6: =C4-C5 -> 21433.19 | D6: =D4-D5 -> 29318.22 | E6: =E4-E5 -> 17463.06 | F6: =F4-F5 -> 30504.26 | G6: =G4-G5 -> 63489.95 | H6: =H4-H5 -> 32300.16 | I6: =I4-I5 -> 22247.92 | ... K6: =K4-K5 -> 34352.44 | L6: =SUM(Quarters!H6:K6) -> 34352.44 | M6: =M4*M24 -> 36489.804 | N6: =N4*N24 -> 27528.562
A7: Other Income | B7: ='Data Sheet'!B25 -> -3789.11 | C7: ='Data Sheet'!C25 -> 10898.41 | D7: ='Data Sheet'!D25 -> 1524.31 | E7: ='Data Sheet'!E25 -> -2883.63 | F7: ='Data Sheet'!F25 -> 179.78 | G7: ='Data Sheet'!G25 -> 1299.99 | H7: ='Data Sheet'!H25 -> 1568.86 | I7: ='Data Sheet'!I25 -> -6005.23 | ... K7: ='Data Sheet'!K25 -> 737.82 | L7: =SUM(Quarters!H7:K7) -> 737.82 | M7: 0 | N7: 0
A8: Depreciation | B8: ='Data Sheet'!B26 -> 5672.88 | C8: ='Data Sheet'!C26 -> 5741.7 | D8: ='Data Sheet'!D26 -> 7341.83 | E8: ='Data Sheet'!E26 -> 8440.73 | F8: ='Data Sheet'!F26 -> 9233.64 | G8: ='Data Sheet'!G26 -> 9100.87 | H8: ='Data Sheet'!H26 -> 9335.2 | I8: ='Data Sheet'!I26 -> 9882.16 | ... K8: ='Data Sheet'!K26 -> 11954.51 | L8: =SUM(Quarters!H8:K8) -> 11954.51 | M8: =+$L8 -> 11954.51 | N8: =+$L8 -> 11954.51
A9: Interest | B9: ='Data Sheet'!B27 -> 5072.2 | C9: ='Data Sheet'!C27 -> 5454.74 | D9: ='Data Sheet'!D27 -> 7660.1 | E9: ='Data Sheet'!E27 -> 7533.46 | F9: ='Data Sheet'!F27 -> 7606.71 | G9: ='Data Sheet'!G27 -> 5462.2 | H9: ='Data Sheet'!H27 -> 6298.7 | I9: ='Data Sheet'!I27 -> 7507.57 | ... K9: ='Data Sheet'!K27 -> 7167.06 | L9: =SUM(Quarters!H9:K9) -> 7167.06 | M9: =+$L9 -> 7167.06 | N9: =+$L9 -> 7167.06
A10: Profit before tax | B10: ='Data Sheet'!B28 -> -1390.56 | C10: ='Data Sheet'!C28 -> 21135.16 | D10: ='Data Sheet'!D28 -> 15840.6 | E10: ='Data Sheet'!E28 -> -1394.76 | F10: ='Data Sheet'!F28 -> 13843.69 | G10: ='Data Sheet'!G28 -> 50226.87 | H10: ='Data Sheet'!H28 -> 18235.12 | I10: ='Data Sheet'!I28 -> -1147.04 | ... K10: ='Data Sheet'!K28 -> 15968.69 | L10: =SUM(Quarters!H10:K10) -> 15968.69 | M10: =M6+M7-SUM(M8:M9) -> 17368.234 | N10: =N6+N7-SUM(N8:N9) -> 8406.9924
A11: Tax | B11: ='Data Sheet'!B29 -> 2778.01 | C11: ='Data Sheet'!C29 -> 3392.33 | D11: ='Data Sheet'!D29 -> 6718.43 | E11: ='Data Sheet'!E29 -> -2568.41 | F11: ='Data Sheet'!F29 -> 5653.9 | G11: ='Data Sheet'!G29 -> 8477.55 | H11: ='Data Sheet'!H29 -> 10159.77 | I11: ='Data Sheet'!I29 -> 3762.57 | ... K11: ='Data Sheet'!K29 -> 5082.87 | L11: =SUM(Quarters!H11:K11) -> 5082.87 | M11: =IF($L10>0,$L11/$L10,0) -> 0.31830225 | N11: =IF($L10>0,$L11/$L10,0) -> 0.31830225
A12: Net profit | B12: ='Data Sheet'!B30 -> -4240.8 | C12: ='Data Sheet'!C30 -> 13434.33 | D12: ='Data Sheet'!D30 -> 10218.33 | E12: ='Data Sheet'!E30 -> 1556.54 | F12: ='Data Sheet'!F30 -> 7490.22 | G12: ='Data Sheet'!G30 -> 40153.93 | H12: ='Data Sheet'!H30 -> 8760.4 | I12: ='Data Sheet'!I30 -> -4437.44 | ... K12: ='Data Sheet'!K30 -> 10793.87 | L12: =SUM(Quarters!H12:K12) -> 10793.87 | M12: =M10-M11*M10 -> 11839.886 | N12: =N10-N11*N10 -> 5731.0278
A13: EPS | B13: =IF('Data Sheet'!B93>0,B12/'Data Sheet'!B93,0) -> -3.7641796 | C13: =IF('Data Sheet'!C93>0,C12/'Data Sheet'!C93,0) -> 11.925937 | D13: =IF('Data Sheet'!D93>0,D12/'Data Sheet'!D93,0) -> 9.070946 | E13: =IF('Data Sheet'!E93>0,E12/'Data Sheet'!E93,0) -> 1.381761 | F13: =IF('Data Sheet'!F93>0,F12/'Data Sheet'!F93,0) -> 6.2596378 | G13: =IF('Data Sheet'!G93>0,G12/'Data Sheet'!G93,0) -> 32.878023 | H13: =IF('Data Sheet'!H93>0,H12/'Data Sheet'!H93,0) -> 7.1680236 | I13: =IF('Data Sheet'!I93>0,I12/'Data Sheet'!I93,0) -> -3.5546441 | ... K13: =IF('Data Sheet'!K93>0,K12/'Data Sheet'!K93,0) -> 8.6465094 | L13: =IF('Data Sheet'!$B6>0,'Profit & Loss'!L12/'Data Sheet'!$B6,0) -> 8.652035 | M13: =IF('Data Sheet'!$B6>0,'Profit & Loss'!M12/'Data Sheet'!$B6,0) -> 9.4904893 | N13: =IF('Data Sheet'!$B6>0,'Profit & Loss'!N12/'Data Sheet'!$B6,0) -> 4.593816
A14: Price to earning | B14: =IF(B15>0,B15/B13,"") -> -12.217802 | C14: =IF(C15>0,C15/C13,"") -> 4.7887221 | D14: =IF(D15>0,D15/D13,"") -> 5.7436126 | E14: =IF(E15>0,E15/E13,"") -> 19.511333 | F14: =IF(F15>0,F15/F13,"") -> 12.970399 | G14: =IF(G15>0,G15/G13,"") -> 3.9759081 | H14: =IF(H15>0,H15/H13,"") -> 14.578635 | I14: =IF(I15>0,I15/I13,"") -> -43.844051 | ... K14: =IF(K15>0,K15/K13,"") -> 22.189301 | L14: =IF(L13>0,L15/L13,0) -> 23.260424 | M14: =M25 -> 33.913728 | N14: =N25 -> 18.145533
A15: Price | B15: ='Data Sheet'!B90 -> 45.99 | C15: ='Data Sheet'!C90 -> 57.11 | D15: ='Data Sheet'!D90 -> 52.1 | E15: ='Data Sheet'!E90 -> 26.96 | F15: ='Data Sheet'!F90 -> 81.19 | G15: ='Data Sheet'!G90 -> 130.72 | H15: ='Data Sheet'!H90 -> 104.5 | I15: ='Data Sheet'!I90 -> 155.85 | ... K15: ='Data Sheet'!K90 -> 191.86 | L15: ='Data Sheet'!B8 -> 201.25 | M15: =M13*M14 -> 321.85788 | N15: =N13*N14 -> 83.35724
A17: RATIOS:
A18: Dividend Payout | B18: =IF('Data Sheet'!B30>0, 'Data Sheet'!B31/'Data Sheet'!B30, 0) -> 0 | C18: =IF('Data Sheet'!C30>0, 'Data Sheet'!C31/'Data Sheet'!C30, 0) -> 0.085225687 | D18: =IF('Data Sheet'!D30>0, 'Data Sheet'!D31/'Data Sheet'!D30, 0) -> 0.14566177 | E18: =IF('Data Sheet'!E30>0, 'Data Sheet'!E31/'Data Sheet'!E30, 0) -> 0.73557377 | F18: =IF('Data Sheet'!F30>0, 'Data Sheet'!F31/'Data Sheet'!F30, 0) -> 0.39972391 | G18: =IF('Data Sheet'!G30>0, 'Data Sheet'!G31/'Data Sheet'!G30, 0) -> 0.15510736 | H18: =IF('Data Sheet'!H30>0, 'Data Sheet'!H31/'Data Sheet'!H30, 0) -> 0.50185608 | I18: =IF('Data Sheet'!I30>0, 'Data Sheet'!I31/'Data Sheet'!I30, 0) -> 0 | ... K18: =IF('Data Sheet'!K30>0, 'Data Sheet'!K31/'Data Sheet'!K30, 0) -> 0.4622772
A19: OPM | B19: =IF(B6>0,B6/B4,0) -> 0.11704094 | C19: =IF(C6>0,C6/C4,0) -> 0.17390143 | D19: =IF(D6>0,D6/D4,0) -> 0.18594792 | E19: =IF(E6>0,E6/E4,0) -> 0.12489972 | F19: =IF(F6>0,F6/F4,0) -> 0.19494355 | G19: =IF(G6>0,G6/G4,0) -> 0.26024826 | H19: =IF(H6>0,H6/H4,0) -> 0.13272983 | I19: =IF(I6>0,I6/I4,0) -> 0.09708009 | ... L19: =IF(L6>0,L6/L4,0) -> 0.1479816
G22: TRENDS: | H22: 10 YEARS | I22: 7 YEARS | J22: 5 YEARS | K22: 3 YEARS | L22: RECENT | M22: BEST | N22: WORST
G23: Sales Growth | H23: =IF(B4=0,"",POWER($K4/B4,1/9)-1) -> 0.084030178 | I23: =IF(D4=0,"",POWER($K4/D4,1/7)-1) -> 0.056818755 | J23: =IF(F4=0,"",POWER($K4/F4,1/5)-1) -> 0.082080696 | K23: =IF(H4=0,"",POWER($K4/H4, 1/3)-1) -> -0.01560083 | L23: =IF(ISERROR(MAX(IF(J4=0,"",(K4-J4)/J4),IF(K4=0,"",(L4-K4)/K4))),"",MAX(IF(J4=0,"",(K4-J4)/J4),IF(K4=0,"",(L4-K4)/K4))) -> 0.062218696 | M23: =MAX(K23:L23) -> 0.062218696 | N23: =MIN(H23:L23) -> -0.01560083
G24: OPM | H24: =IF(SUM(B4:$K$4)=0,"",SUMPRODUCT(B19:$K$19,B4:$K$4)/SUM(B4:$K$4)) -> 0.15595138 | I24: =IF(SUM(E4:$K$4)=0,"",SUMPRODUCT(E19:$K$19,E4:$K$4)/SUM(E4:$K$4)) -> 0.15419374 | J24: =IF(SUM(G4:$K$4)=0,"",SUMPRODUCT(G19:$K$19,G4:$K$4)/SUM(G4:$K$4)) -> 0.15223975 | K24: =IF(SUM(I4:$K$4)=0, "", SUMPRODUCT(I19:$K$19,I4:$K$4)/SUM(I4:$K$4)) -> 0.12046543 | L24: =L19 -> 0.1479816 | M24: =MAX(K24:L24) -> 0.1479816 | N24: =MIN(H24:L24) -> 0.12046543
G25: Price to Earning | H25: =IF(ISERROR(AVERAGEIF(B14:$L14,">0")),"",AVERAGEIF(B14:$L14,">0")) -> 18.145533 | I25: =IF(ISERROR(AVERAGEIF(E14:$L14,">0")),"",AVERAGEIF(E14:$L14,">0")) -> 21.825352 | J25: =IF(ISERROR(AVERAGEIF(G14:$L14,">0")),"",AVERAGEIF(G14:$L14,">0")) -> 24.059146 | K25: =IF(ISERROR(AVERAGEIF(I14:$L14,">0")),"",AVERAGEIF(I14:$L14,">0")) -> 33.913728 | L25: =L14 -> 23.260424 | M25: =MAX(K25:L25) -> 33.913728 | N25: =MIN(H25:L25) -> 18.145533

Sheet Quarters
A1: ='Profit & Loss'!A1 -> TATA STEEL LTD | J1: SCREENER.IN
A3: Narration | B3: ='Data Sheet'!B41 -> 45291 | C3: ='Data Sheet'!C41 -> 45382 | D3: ='Data Sheet'!D41 -> 45473 | E3: ='Data Sheet'!E41 -> 45565 | F3: ='Data Sheet'!F41 -> 45657 | G3: ='Data Sheet'!G41 -> 45747 | H3: ='Data Sheet'!H41 -> 45838 | I3: ='Data Sheet'!I41 -> 45930 | ... K3: ='Data Sheet'!K41 -> 46112
A4: Sales | B4: ='Data Sheet'!B42 -> 55311.88 | C4: ='Data Sheet'!C42 -> 58687.31 | D4: ='Data Sheet'!D42 -> 54771.39 | E4: ='Data Sheet'!E42 -> 53904.71 | F4: ='Data Sheet'!F42 -> 53648.3 | G4: ='Data Sheet'!G42 -> 56218.11 | H4: ='Data Sheet'!H42 -> 53178.12 | I4: ='Data Sheet'!I42 -> 58689.29 | ... K4: ='Data Sheet'!K42 -> 63270.13
A5: Expenses | B5: ='Data Sheet'!B43 -> 49048.31 | C5: ='Data Sheet'!C43 -> 52086.68 | D5: ='Data Sheet'!D43 -> 48076.92 | E5: ='Data Sheet'!E43 -> 47788.92 | F5: ='Data Sheet'!F43 -> 47744.81 | G5: ='Data Sheet'!G43 -> 49658.89 | H5: ='Data Sheet'!H43 -> 45750.58 | I5: ='Data Sheet'!I43 -> 49792.75 | ... K5: ='Data Sheet'!K43 -> 53441.47
A6: Operating Profit | B6: ='Data Sheet'!B50 -> 6263.57 | C6: ='Data Sheet'!C50 -> 6600.63 | D6: ='Data Sheet'!D50 -> 6694.47 | E6: ='Data Sheet'!E50 -> 6115.79 | F6: ='Data Sheet'!F50 -> 5903.49 | G6: ='Data Sheet'!G50 -> 6559.22 | H6: ='Data Sheet'!H50 -> 7427.54 | I6: ='Data Sheet'!I50 -> 8896.54 | ... K6: ='Data Sheet'!K50 -> 9828.66
A7: Other Income | B7: ='Data Sheet'!B44 -> -32.84 | C7: ='Data Sheet'!C44 -> -381.56 | D7: ='Data Sheet'!D44 -> -5.51 | E7: ='Data Sheet'!E44 -> 616.68 | F7: ='Data Sheet'!F44 -> 141.82 | G7: ='Data Sheet'!G44 -> 149.19 | H7: ='Data Sheet'!H44 -> 236.27 | I7: ='Data Sheet'!I44 -> -6.11 | ... K7: ='Data Sheet'!K44 -> 42.49
A8: Depreciation | B8: ='Data Sheet'!B45 -> 2422.04 | C8: ='Data Sheet'!C45 -> 2567.95 | D8: ='Data Sheet'!D45 -> 2535.43 | E8: ='Data Sheet'!E45 -> 2596.74 | F8: ='Data Sheet'!F45 -> 2569.19 | G8: ='Data Sheet'!G45 -> 2719.97 | H8: ='Data Sheet'!H45 -> 2744.3 | I8: ='Data Sheet'!I45 -> 2893 | ... K8: ='Data Sheet'!K45 -> 3268.4
A9: Interest | B9: ='Data Sheet'!B46 -> 1880.78 | C9: ='Data Sheet'!C46 -> 1842.25 | D9: ='Data Sheet'!D46 -> 1776.71 | E9: ='Data Sheet'!E46 -> 1971.4 | F9: ='Data Sheet'!F46 -> 1804.09 | G9: ='Data Sheet'!G46 -> 1788.75 | H9: ='Data Sheet'!H46 -> 1852.43 | I9: ='Data Sheet'!I46 -> 1774.96 | ... K9: ='Data Sheet'!K46 -> 1792.38
A10: Profit before tax | B10: ='Data Sheet'!B47 -> 1927.91 | C10: ='Data Sheet'!C47 -> 1808.87 | D10: ='Data Sheet'!D47 -> 2376.82 | E10: ='Data Sheet'!E47 -> 2164.33 | F10: ='Data Sheet'!F47 -> 1672.03 | G10: ='Data Sheet'!G47 -> 2199.69 | H10: ='Data Sheet'!H47 -> 3067.08 | I10: ='Data Sheet'!I47 -> 4222.47 | ... K10: ='Data Sheet'!K47 -> 4810.37
A11: Tax | B11: ='Data Sheet'!B48 -> 1405.77 | C11: ='Data Sheet'!C48 -> 1254.31 | D11: ='Data Sheet'!D48 -> 1458.25 | E11: ='Data Sheet'!E48 -> 1405.49 | F11: ='Data Sheet'!F48 -> 1376.54 | G11: ='Data Sheet'!G48 -> 998.81 | H11: ='Data Sheet'!H48 -> 1059.72 | I11: ='Data Sheet'!I48 -> 1039.38 | ... K11: ='Data Sheet'!K48 -> 1845.37
A12: Net profit | B12: ='Data Sheet'!B49 -> 513.37 | C12: ='Data Sheet'!C49 -> 611.48 | D12: ='Data Sheet'!D49 -> 959.61 | E12: ='Data Sheet'!E49 -> 833.45 | F12: ='Data Sheet'!F49 -> 326.64 | G12: ='Data Sheet'!G49 -> 1300.81 | H12: ='Data Sheet'!H49 -> 2077.68 | I12: ='Data Sheet'!I49 -> 3101.75 | ... K12: ='Data Sheet'!K49 -> 2925.74
A14: OPM | B14: =IF(B4>0,B6/B4,"") -> 0.11324095 | C14: =IF(C4>0,C6/C4,"") -> 0.11247116 | D14: =IF(D4>0,D6/D4,"") -> 0.12222567 | E14: =IF(E4>0,E6/E4,"") -> 0.11345558 | F14: =IF(F4>0,F6/F4,"") -> 0.11004058 | G14: =IF(G4>0,G6/G4,"") -> 0.1166745 | H14: =IF(H4>0,H6/H4,"") -> 0.13967286 | I14: =IF(I4>0,I6/I4,"") -> 0.15158711 | ... K14: =IF(K4>0,K6/K4,"") -> 0.15534439

Sheet Balance Sheet
A1: ='Profit & Loss'!A1 -> TATA STEEL LTD | J1: SCREENER.IN
A3: Narration | B3: ='Data Sheet'!B56 -> 42825 | C3: ='Data Sheet'!C56 -> 43190 | D3: ='Data Sheet'!D56 -> 43555 | E3: ='Data Sheet'!E56 -> 43921 | F3: ='Data Sheet'!F56 -> 44286 | G3: ='Data Sheet'!G56 -> 44651 | H3: ='Data Sheet'!H56 -> 45016 | I3: ='Data Sheet'!I56 -> 45382 | ... K3: ='Data Sheet'!K56 -> 46112
A4: Equity Share Capital | B4: ='Data Sheet'!B57 -> 970.24 | C4: ='Data Sheet'!C57 -> 1144.95 | D4: ='Data Sheet'!D57 -> 1144.94 | E4: ='Data Sheet'!E57 -> 1144.95 | F4: ='Data Sheet'!F57 -> 1197.61 | G4: ='Data Sheet'!G57 -> 1221.21 | H4: ='Data Sheet'!H57 -> 1221.24 | I4: ='Data Sheet'!I57 -> 1247.44 | ... K4: ='Data Sheet'!K57 -> 1247.44
A5: Reserves | B5: ='Data Sheet'!B58 -> 36849.08 | C5: ='Data Sheet'!C58 -> 59725.67 | D5: ='Data Sheet'!D58 -> 67780.14 | E5: ='Data Sheet'!E58 -> 72431.35 | F5: ='Data Sheet'!F58 -> 73041.16 | G5: ='Data Sheet'!G58 -> 113221.83 | H5: ='Data Sheet'!H58 -> 101860.86 | I5: ='Data Sheet'!I58 -> 90788.32 | ... K5: ='Data Sheet'!K58 -> 100920.21
A6: Borrowings | B6: ='Data Sheet'!B59 -> 83014.49 | C6: ='Data Sheet'!C59 -> 92147.05 | D6: ='Data Sheet'!D59 -> 100816.22 | E6: ='Data Sheet'!E59 -> 116328.2 | F6: ='Data Sheet'!F59 -> 88501.41 | G6: ='Data Sheet'!G59 -> 75561.35 | H6: ='Data Sheet'!H59 -> 84893.05 | I6: ='Data Sheet'!I59 -> 87082.12 | ... K6: ='Data Sheet'!K59 -> 92381.68
A7: Other Liabilities | B7: ='Data Sheet'!B60 -> 51613.56 | C7: ='Data Sheet'!C60 -> 55704.47 | D7: ='Data Sheet'!D60 -> 63032.14 | E7: ='Data Sheet'!E60 -> 59244.62 | F7: ='Data Sheet'!F60 -> 81169.01 | G7: ='Data Sheet'!G60 -> 92417.28 | H7: ='Data Sheet'!H60 -> 97420.63 | I7: ='Data Sheet'!I60 -> 90194.54 | ... K7: ='Data Sheet'!K60 -> 101965.29
A8: Total | B8: ='Data Sheet'!B61 -> 172447.37 | C8: ='Data Sheet'!C61 -> 208722.14 | D8: ='Data Sheet'!D61 -> 232773.44 | E8: ='Data Sheet'!E61 -> 249149.12 | F8: ='Data Sheet'!F61 -> 243909.19 | G8: ='Data Sheet'!G61 -> 282421.67 | H8: ='Data Sheet'!H61 -> 285395.78 | I8: ='Data Sheet'!I61 -> 269312.42 | ... K8: ='Data Sheet'!K61 -> 296514.62
A10: Net Block | B10: ='Data Sheet'!B62 -> 92006.55 | C10: ='Data Sheet'!C62 -> 96104.89 | D10: ='Data Sheet'!D62 -> 124441.91 | E10: ='Data Sheet'!E62 -> 134550.66 | F10: ='Data Sheet'!F62 -> 135775.18 | G10: ='Data Sheet'!G62 -> 133287.83 | H10: ='Data Sheet'!H62 -> 146621.46 | I10: ='Data Sheet'!I62 -> 148814.38 | ... K10: ='Data Sheet'!K62 -> 179908.13
A11: Capital Work in Progress | B11: ='Data Sheet'!B63 -> 15784.13 | C11: ='Data Sheet'!C63 -> 16614.41 | D11: ='Data Sheet'!D63 -> 18641.21 | E11: ='Data Sheet'!E63 -> 19496.83 | F11: ='Data Sheet'!F63 -> 19007.4 | G11: ='Data Sheet'!G63 -> 22045.55 | H11: ='Data Sheet'!H63 -> 31213.02 | I11: ='Data Sheet'!I63 -> 34355.53 | ... K11: ='Data Sheet'!K63 -> 28496.71
A12: Investments | B12: ='Data Sheet'!B64 -> 12457.12 | C12: ='Data Sheet'!C64 -> 17899.47 | D12: ='Data Sheet'!D64 -> 5738.17 | E12: ='Data Sheet'!E64 -> 6285.18 | F12: ='Data Sheet'!F64 -> 10681.93 | G12: ='Data Sheet'!G64 -> 13139.85 | H12: ='Data Sheet'!H64 -> 8410.31 | I12: ='Data Sheet'!I64 -> 6257.57 | ... K12: ='Data Sheet'!K64 -> 7088.85
A13: Other Assets | B13: ='Data Sheet'!B65 -> 52199.57 | C13: ='Data Sheet'!C65 -> 78103.37 | D13: ='Data Sheet'!D65 -> 83952.15 | E13: ='Data Sheet'!E65 -> 88816.45 | F13: ='Data Sheet'!F65 -> 78444.68 | G13: ='Data Sheet'!G65 -> 113948.44 | H13: ='Data Sheet'!H65 -> 99150.99 | I13: ='Data Sheet'!I65 -> 79884.94 | ... K13: ='Data Sheet'!K65 -> 81020.93
A14: Total | B14: ='Data Sheet'!B66 -> 172447.37 | C14: ='Data Sheet'!C66 -> 208722.14 | D14: ='Data Sheet'!D66 -> 232773.44 | E14: ='Data Sheet'!E66 -> 249149.12 | F14: ='Data Sheet'!F66 -> 243909.19 | G14: ='Data Sheet'!G66 -> 282421.67 | H14: ='Data Sheet'!H66 -> 285395.78 | I14: ='Data Sheet'!I66 -> 269312.42 | ... K14: ='Data Sheet'!K66 -> 296514.62
A16: Working Capital | B16: =B13-B7 -> 586.01 | C16: =C13-C7 -> 22398.9 | D16: =D13-D7 -> 20920.01 | E16: =E13-E7 -> 29571.83 | F16: =F13-F7 -> -2724.33 | G16: =G13-G7 -> 21531.16 | H16: =H13-H7 -> 1730.36 | I16: =I13-I7 -> -10309.6 | ... K16: =K13-K7 -> -20944.36
A17: Debtors | B17: ='Data Sheet'!B67 -> 11586.82 | C17: ='Data Sheet'!C67 -> 12415.52 | D17: ='Data Sheet'!D67 -> 11811 | E17: ='Data Sheet'!E67 -> 7884.91 | F17: ='Data Sheet'!F67 -> 9539.84 | G17: ='Data Sheet'!G67 -> 12246.43 | H17: ='Data Sheet'!H67 -> 8257.24 | I17: ='Data Sheet'!I67 -> 6263.53 | ... K17: ='Data Sheet'!K67 -> 4916.89
A18: Inventory | B18: ='Data Sheet'!B68 -> 24803.82 | C18: ='Data Sheet'!C68 -> 28331.04 | D18: ='Data Sheet'!D68 -> 31656.1 | E18: ='Data Sheet'!E68 -> 31068.72 | F18: ='Data Sheet'!F68 -> 33276.38 | G18: ='Data Sheet'!G68 -> 48824.39 | H18: ='Data Sheet'!H68 -> 54415.33 | I18: ='Data Sheet'!I68 -> 49157.51 | ... K18: ='Data Sheet'!K68 -> 47249.22
A20: Debtor Days | B20: =IF('Profit & Loss'!B4>0,'Balance Sheet'!B17/('Profit & Loss'!B4/365),0) -> 37.659939 | C20: =IF('Profit & Loss'!C4>0,'Balance Sheet'!C17/('Profit & Loss'!C4/365),0) -> 36.768349 | D20: =IF('Profit & Loss'!D4>0,'Balance Sheet'!D17/('Profit & Loss'!D4/365),0) -> 27.342187 | E20: =IF('Profit & Loss'!E4>0,'Balance Sheet'!E17/('Profit & Loss'!E4/365),0) -> 20.584045 | F20: =IF('Profit & Loss'!F4>0,'Balance Sheet'!F17/('Profit & Loss'!F4/365),0) -> 22.252681 | G20: =IF('Profit & Loss'!G4>0,'Balance Sheet'!G17/('Profit & Loss'!G4/365),0) -> 18.322521 | H20: =IF('Profit & Loss'!H4>0,'Balance Sheet'!H17/('Profit & Loss'!H4/365),0) -> 12.384875 | I20: =IF('Profit & Loss'!I4>0,'Balance Sheet'!I17/('Profit & Loss'!I4/365),0) -> 9.975916 | ... K20: =IF('Profit & Loss'!K4>0,'Balance Sheet'!K17/('Profit & Loss'!K4/365),0) -> 7.7309611
A21: Inventory Turnover | B21: =IF('Balance Sheet'!B18>0,'Profit & Loss'!B4/'Balance Sheet'!B18,0) -> 4.527505 | C21: =IF('Balance Sheet'!C18>0,'Profit & Loss'!C4/'Balance Sheet'!C18,0) -> 4.3503193 | D21: =IF('Balance Sheet'!D18>0,'Profit & Loss'!D4/'Balance Sheet'!D18,0) -> 4.9806827 | E21: =IF('Balance Sheet'!E18>0,'Profit & Loss'!E4/'Balance Sheet'!E18,0) -> 4.5002385 | F21: =IF('Balance Sheet'!F18>0,'Profit & Loss'!F4/'Balance Sheet'!F18,0) -> 4.7023564 | G21: =IF('Balance Sheet'!G18>0,'Profit & Loss'!G4/'Balance Sheet'!G18,0) -> 4.996666 | H21: =IF('Balance Sheet'!H18>0,'Profit & Loss'!H4/'Balance Sheet'!H18,0) -> 4.4721348 | I21: =IF('Balance Sheet'!I18>0,'Profit & Loss'!I4/'Balance Sheet'!I18,0) -> 4.6619688 | ... K21: =IF('Balance Sheet'!K18>0,'Profit & Loss'!K4/'Balance Sheet'!K18,0) -> 4.9130957
A23: Return on Equity | B23: =IF(SUM('Balance Sheet'!B4:B5)>0,'Profit & Loss'!B12/SUM('Balance Sheet'!B4:B5),"") -> -0.11213316 | C23: =IF(SUM('Balance Sheet'!C4:C5)>0,'Profit & Loss'!C12/SUM('Balance Sheet'!C4:C5),"") -> 0.22070303 | D23: =IF(SUM('Balance Sheet'!D4:D5)>0,'Profit & Loss'!D12/SUM('Balance Sheet'!D4:D5),"") -> 0.14825271 | E23: =IF(SUM('Balance Sheet'!E4:E5)>0,'Profit & Loss'!E12/SUM('Balance Sheet'!E4:E5),"") -> 0.021155454 | F23: =IF(SUM('Balance Sheet'!F4:F5)>0,'Profit & Loss'!F12/SUM('Balance Sheet'!F4:F5),"") -> 0.10089364 | G23: =IF(SUM('Balance Sheet'!G4:G5)>0,'Profit & Loss'!G12/SUM('Balance Sheet'!G4:G5),"") -> 0.35086389 | H23: =IF(SUM('Balance Sheet'!H4:H5)>0,'Profit & Loss'!H12/SUM('Balance Sheet'!H4:H5),"") -> 0.084984687 | I23: =IF(SUM('Balance Sheet'!I4:I5)>0,'Profit & Loss'!I12/SUM('Balance Sheet'!I4:I5),"") -> -0.048214303 | ... K23: =IF(SUM('Balance Sheet'!K4:K5)>0,'Profit & Loss'!K12/SUM('Balance Sheet'!K4:K5),"") -> 0.10564861
A24: Return on Capital Emp | C24: =IF((B4+B5+B6+C4+C5+C6)>0,('Profit & Loss'!C10+'Profit & Loss'!C9)*2/(B4+B5+B6+C4+C5+C6),"") -> 0.19419212 | D24: =IF((C4+C5+C6+D4+D5+D6)>0,('Profit & Loss'!D10+'Profit & Loss'!D9)*2/(C4+C5+C6+D4+D5+D6),"") -> 0.14562384 | E24: =IF((D4+D5+D6+E4+E5+E6)>0,('Profit & Loss'!E10+'Profit & Loss'!E9)*2/(D4+D5+D6+E4+E5+E6),"") -> 0.034137476 | F24: =IF((E4+E5+E6+F4+F5+F6)>0,('Profit & Loss'!F10+'Profit & Loss'!F9)*2/(E4+E5+E6+F4+F5+F6),"") -> 0.12165447 | G24: =IF((F4+F5+F6+G4+G5+G6)>0,('Profit & Loss'!G10+'Profit & Loss'!G9)*2/(F4+F5+F6+G4+G5+G6),"") -> 0.31574728 | H24: =IF((G4+G5+G6+H4+H5+H6)>0,('Profit & Loss'!H10+'Profit & Loss'!H9)*2/(G4+G5+G6+H4+H5+H6),"") -> 0.1298156 | I24: =IF((H4+H5+H6+I4+I5+I6)>0,('Profit & Loss'!I10+'Profit & Loss'!I9)*2/(H4+H5+H6+I4+I5+I6),"") -> 0.034653505 | J24: =IF((I4+I5+I6+J4+J5+J6)>0,('Profit & Loss'!J10+'Profit & Loss'!J9)*2/(I4+I5+I6+J4+J5+J6),"") -> 0.086301362 | K24: =IF((J4+J5+J6+K4+K5+K6)>0,('Profit & Loss'!K10+'Profit & Loss'!K9)*2/(J4+J5+J6+K4+K5+K6),"") -> 0.1216007

Sheet Cash Flow
A1: ='Balance Sheet'!A1 -> TATA STEEL LTD | J1: SCREENER.IN
A3: Narration | B3: ='Data Sheet'!B81 -> 42825 | C3: ='Data Sheet'!C81 -> 43190 | D3: ='Data Sheet'!D81 -> 43555 | E3: ='Data Sheet'!E81 -> 43921 | F3: ='Data Sheet'!F81 -> 44286 | G3: ='Data Sheet'!G81 -> 44651 | H3: ='Data Sheet'!H81 -> 45016 | I3: ='Data Sheet'!I81 -> 45382 | ... K3: ='Data Sheet'!K81 -> 46112
A4: Cash from Operating Activity | B4: ='Data Sheet'!B82 -> 10824.36 | C4: ='Data Sheet'!C82 -> 8023.39 | D4: ='Data Sheet'!D82 -> 25335.95 | E4: ='Data Sheet'!E82 -> 20168.72 | F4: ='Data Sheet'!F82 -> 44326.68 | G4: ='Data Sheet'!G82 -> 44380.99 | H4: ='Data Sheet'!H82 -> 21683.08 | I4: ='Data Sheet'!I82 -> 20300.67 | ... K4: ='Data Sheet'!K82 -> 35064.46
A5: Cash from Investing Activity | B5: ='Data Sheet'!B83 -> -9489.65 | C5: ='Data Sheet'!C83 -> -11730.31 | D5: ='Data Sheet'!D83 -> -29176.45 | E5: ='Data Sheet'!E83 -> -14012.06 | F5: ='Data Sheet'!F83 -> -9437.27 | G5: ='Data Sheet'!G83 -> -10905.02 | H5: ='Data Sheet'!H83 -> -18179.45 | I5: ='Data Sheet'!I83 -> -14252.74 | ... K5: ='Data Sheet'!K83 -> -14397.35
A6: Cash from Financing Activity | B6: ='Data Sheet'!B84 -> -2579.36 | C6: ='Data Sheet'!C84 -> 6639.94 | D6: ='Data Sheet'!D84 -> -672.7 | E6: ='Data Sheet'!E84 -> -1694.62 | F6: ='Data Sheet'!F84 -> -37089.67 | G6: ='Data Sheet'!G84 -> -23401.09 | H6: ='Data Sheet'!H84 -> -6980.69 | I6: ='Data Sheet'!I84 -> -11096.99 | ... K6: ='Data Sheet'!K84 -> -21387.12
A7: Net Cash Flow | B7: ='Data Sheet'!B85 -> -1244.65 | C7: ='Data Sheet'!C85 -> 2933.02 | D7: ='Data Sheet'!D85 -> -4513.2 | E7: ='Data Sheet'!E85 -> 4462.04 | F7: ='Data Sheet'!F85 -> -2200.26 | G7: ='Data Sheet'!G85 -> 10074.88 | H7: ='Data Sheet'!H85 -> -3477.06 | I7: ='Data Sheet'!I85 -> -5049.06 | ... K7: ='Data Sheet'!K85 -> -720.01

Sheet Customization
A1: How to use it?
A3: You can customize this workbook as you want.
B4: You can add custom formating, add conditional formating, add your own formulas… do ANYTHING.
B5: Please don't edit the "Data Sheet" only.
A7: After customization, you can upload this back on Screener.
B8: Upload on: | C8: https://www.screener.in/excel/
A10: Download your customized workbooks now onwards.
B11: Now whenever you will "Export to excel" from Screener, it will export your customized file.
A14: TESTING:
B15: This is a testing feature currently.
B16: You can report any formula errors on the worksheet at: support@screener.in

Sheet Financials>

Sheet FM
B2: TATA STEEL LTD.
B3: IN Crores | D3: 2024 | E3: 2025 | F3: 2026 | G3: 2027 | H3: 2028 | I3: 2029
A5: # | B5: ="Income Statement"&"-"&$B$2 -> Income Statement-TATA STEEL LTD.
B6: Revenue | D6: =IFERROR('Data Sheet'!I17,0) -> 229170.78 | E6: =IFERROR('Data Sheet'!J17,0) -> 218542.51 | F6: =IFERROR('Data Sheet'!K17,0) -> 232139.94 | G6: =F6*(1+G24) -> 244907.64 | H6: =G6*(1+H24) -> 258377.56 | I6: =H6*(1+I24) -> 272588.32
B7: COGS | D7: =IFERROR(SUM('Data Sheet'!I18,'Data Sheet'!I19,'Data Sheet'!I20,'Data Sheet'!I21),0) -> 149826.56 | E7: =IFERROR(SUM('Data Sheet'!J18,'Data Sheet'!J19,'Data Sheet'!J20,'Data Sheet'!J21),0) -> 147019.3 | F7: =IFERROR(SUM('Data Sheet'!K18,'Data Sheet'!K19,'Data Sheet'!K20,'Data Sheet'!K21),0) -> 143457.56 | G7: =G6*G25 -> 157123.6 | H7: =H6*H25 -> 165547.73 | I7: =I6*I25 -> 173481.94
B8: Gross Profit | D8: =D6-D7 -> 79344.22 | E8: =E6-E7 -> 71523.21 | F8: =F6-F7 -> 88682.38 | G8: =G6-G7 -> 87784.039 | H8: =H6-H7 -> 92829.827 | I8: =I6-I7 -> 99106.386
B9: Selling and Administration | D9: =IFERROR('Data Sheet'!I23,0) -> 14453.57 | E9: =IFERROR('Data Sheet'!J23,0) -> 12137.26 | F9: =IFERROR('Data Sheet'!K23,0) -> 13348.99 | G9: =G6*G28 -> 14211.26 | H9: =H6*H28 -> 14823.686 | I9: =I6*I28 -> 15699.728
B10: Other Expenses | D10: =IFERROR('Data Sheet'!I24,0) -> 9314.45 | E10: =IFERROR('Data Sheet'!J24,0) -> 9391.81 | F10: =IFERROR('Data Sheet'!K24,0) -> 13002.73 | G10: =G6*G29 -> 12007.206 | H10: =H6*H29 -> 12896.252 | I10: =I6*I29 -> 13865.738
B11: Employee Cost | D11: =IFERROR('Data Sheet'!I22,0) -> 24509.58 | E11: =IFERROR('Data Sheet'!J22,0) -> 24888.99 | F11: =IFERROR('Data Sheet'!K22,0) -> 25998.98 | G11: =G6*G27 -> 27320.471 | H11: =H6*H27 -> 28977.934 | I11: =I6*I27 -> 30514.186
B12: EBITDA | D12: =IFERROR(D8-SUM(D9,D10,D11),0) -> 31066.62 | E12: =IFERROR(E8-SUM(E9,E10,E11),0) -> 25105.15 | F12: =IFERROR(F8-SUM(F9,F10,F11),0) -> 36331.68 | G12: =IFERROR(G8-SUM(G9,G10,G11),0) -> 34245.102 | H12: =IFERROR(H8-SUM(H9,H10,H11),0) -> 36131.955 | I12: =IFERROR(I8-SUM(I9,I10,I11),0) -> 39026.735
B13: Depreciation | D13: =IFERROR('Data Sheet'!I26,0) -> 9882.16 | E13: =IFERROR('Data Sheet'!J26,0) -> 10421.33 | F13: =IFERROR('Data Sheet'!K26,0) -> 11954.51 | G13: =G6*G30 -> 11921.725 | H13: =H6*H30 -> 12744.588 | I13: =I6*I30 -> 13511.02
B14: EBIT | D14: =D12-D13 -> 21184.46 | E14: =E12-E13 -> 14683.82 | F14: =F12-F13 -> 24377.17 | G14: =G12-G13 -> 22323.377 | H14: =H12-H13 -> 23387.367 | I14: =I12-I13 -> 25515.715
B15: Other Income | D15: =IFERROR('Data Sheet'!I25,0) -> -6005.23 | E15: =IFERROR('Data Sheet'!J25,0) -> 876.7 | F15: =IFERROR('Data Sheet'!K25,0) -> 737.82 | G15: =G6*G32 -> 734.72291 | H15: =H6*H32 -> 775.13267 | I15: =I6*I32 -> 817.76497
B16: Interest | D16: =IFERROR('Data Sheet'!I27,0) -> 7507.57 | E16: =IFERROR('Data Sheet'!J27,0) -> 7340.95 | F16: =IFERROR('Data Sheet'!K27,0) -> 7167.06 | G16: =G6*G31 -> 7853.2154 | H16: =H6*H31 -> 8271.512 | I16: =I6*I31 -> 8668.6418
B17: Exceptional Items | D17: 8818.7 | E17: 193.3 | F17: 1979.24 | G17: 0 | H17: 0 | I17: 0
B18: EBT | D18: =IFERROR(D14+D15-D16-D17,0) -> -1147.04 | E18: =IFERROR(E14+E15-E16-E17,0) -> 8026.27 | F18: =IFERROR(F14+F15-F16-F17,0) -> 15968.69 | G18: =IFERROR(G14+G15-G16-G17,0) -> 15204.884 | H18: =IFERROR(H14+H15-H16-H17,0) -> 15890.987 | I18: =IFERROR(I14+I15-I16-I17,0) -> 17664.838
B19: Taxes | D19: =IFERROR('Data Sheet'!I29,0) -> 3762.57 | E19: =IFERROR('Data Sheet'!J29,0) -> 5239.09 | F19: =IFERROR('Data Sheet'!K29,0) -> 5082.87 | G19: =G18*G33 -> 4257.3677 | H19: =H18*H33 -> 4449.4765 | I19: =I18*I33 -> 4946.1548
B20: Net Income | D20: =IFERROR(D18-D19,0) -> -4909.61 | E20: =IFERROR(E18-E19,0) -> 2787.18 | F20: =IFERROR(F18-F19,0) -> 10885.82 | G20: =IFERROR(G18-G19,0) -> 10947.517 | H20: =IFERROR(H18-H19,0) -> 11441.511 | I20: =IFERROR(I18-I19,0) -> 12718.684
A22: # | B22: ="Assumptions"&"-"&$B$2 -> Assumptions-TATA STEEL LTD.
B24: Revenue Growth (%) | D24: NA | E24: =IFERROR(E6/D6-1,0) -> -0.046377073 | F24: =IFERROR(F6/E6-1,0) -> 0.062218696 | G24: 0.055 | H24: =G24 -> 0.055 | I24: =H24 -> 0.055
B25: COGS as % of Revenue | D25: =IFERROR(D7/D6,0) -> 0.65377689 | E25: =IFERROR(E7/E6,0) -> 0.67272633 | F25: =IFERROR(F7/F6,0) -> 0.61797879 | G25: =(D25*0.2)+(E25*0.3)+(F25*0.5) -> 0.64156267 | H25: =(E25*0.2)+(F25*0.3)+(G25*0.5) -> 0.64072024 | I25: =(F25*0.2)+(G25*0.3)+(H25*0.5) -> 0.63642468
B26: Gross Margin (%) | D26: =IFERROR(D8/D6,0) -> 0.34622311 | E26: =IFERROR(E8/E6,0) -> 0.32727367 | F26: =IFERROR(F8/F6,0) -> 0.38202121 | G26: =IFERROR(G8/G6,0) -> 0.35843733 | H26: =IFERROR(H8/H6,0) -> 0.35927976 | I26: =IFERROR(I8/I6,0) -> 0.36357532
B27: Employee Cost as % Rev | D27: =IFERROR(D11/D6,0) -> 0.10694897 | E27: =IFERROR(E11/E6,0) -> 0.11388626 | F27: =IFERROR(F11/F6,0) -> 0.11199701 | G27: =(D27*0.2)+(E27*0.3)+(F27*0.5) -> 0.11155418 | H27: =(E27*0.2)+(F27*0.3)+(G27*0.5) -> 0.11215345 | I27: =(F27*0.2)+(G27*0.3)+(H27*0.5) -> 0.11194238
B28: SG&A as % Revenue | D28: =IFERROR(D9/D6,0) -> 0.063068992 | E28: =IFERROR(E9/E6,0) -> 0.055537296 | F28: =IFERROR(F9/F6,0) -> 0.057504064 | G28: =(D28*0.2)+(E28*0.3)+(F28*0.5) -> 0.058027019 | H28: =(E28*0.2)+(F28*0.3)+(G28*0.5) -> 0.057372188 | I28: =(F28*0.2)+(G28*0.3)+(H28*0.5) -> 0.057595013
B29: Other Expenses as % Rev | D29: =IFERROR(D10/D6,0) -> 0.040644143 | E29: =IFERROR(E10/E6,0) -> 0.042974751 | F29: =IFERROR(F10/F6,0) -> 0.056012464 | G29: =(D29*0.2)+(E29*0.3)+(F29*0.5) -> 0.049027486 | H29: =(E29*0.2)+(F29*0.3)+(G29*0.5) -> 0.049912432 | I29: =(F29*0.2)+(G29*0.3)+(H29*0.5) -> 0.050866955
B30: Depreciation % Revenue | D30: =IFERROR(D13/D6,0) -> 0.043121379 | E30: =IFERROR(E13/E6,0) -> 0.047685597 | F30: =IFERROR(F13/F6,0) -> 0.051496998 | G30: =(D30*0.2)+(E30*0.3)+(F30*0.5) -> 0.048678454 | H30: =(E30*0.2)+(F30*0.3)+(G30*0.5) -> 0.049325446 | I30: =(F30*0.2)+(G30*0.3)+(H30*0.5) -> 0.049565658
B31: Interest Expense % Revenue | D31: =IFERROR(D16/D6,0) -> 0.032759717 | E31: =IFERROR(E16/E6,0) -> 0.03359049 | F31: =IFERROR(F16/F6,0) -> 0.030873877 | G31: =(D31*0.2)+(E31*0.3)+(F31*0.5) -> 0.032066029 | H31: =(E31*0.2)+(F31*0.3)+(G31*0.5) -> 0.032013276 | I31: =(F31*0.2)+(G31*0.3)+(H31*0.5) -> 0.031801222
B32: Other Income % Revenue | D32: =IFERROR(D15/D6,0) -> -0.02620417 | E32: =IFERROR(E15/E6,0) -> 0.0040115765 | F32: =IFERROR(F15/F6,0) -> 0.0031783415 | G32: 0.003 | H32: =G32 -> 0.003 | I32: =H32 -> 0.003
B33: Effective Tax Rate (%) | D33: =IFERROR(IF(D18=0,0,D19/D18),0) -> -3.2802431 | E33: =IFERROR(IF(E18<0,0,MIN(E19/E18,0.35)),0) -> 0.35 | F33: =IFERROR(IF(F18<0,"",F19/F18),0) -> 0.31830225 | G33: 0.28 | H33: 0.28 | I33: 0.28
B34: Receivables % of Revenue | D34: =D58/D6 -> 0.027331277 | E34: =E58/E6 -> 0.024068818 | F34: =F58/F6 -> 0.021180715 | G34: =(D34*0.2)+(E34*0.3)+(F34*0.5) -> 0.023277259 | H34: =(E34*0.2)+(F34*0.3)+(G34*0.5) -> 0.022806608 | I34: =(F34*0.2)+(G34*0.3)+(H34*0.5) -> 0.022622624
B35: Inventory % of COGS | D35: =D59/D7 -> 0.3280961 | E35: =E59/E7 -> 0.30329311 | F35: =F59/F7 -> 0.32936027 | G35: =(D35*0.2)+(E35*0.3)+(F35*0.5) -> 0.32128728 | H35: =(E35*0.2)+(F35*0.3)+(G35*0.5) -> 0.32011034 | I35: =(F35*0.2)+(G35*0.3)+(H35*0.5) -> 0.32231341
B36: Receivables Days | D36: =D34*365 -> 9.975916 | E36: =E34*365 -> 8.7851187 | F36: =F34*365 -> 7.7309611 | G36: =(D36*0.2)+(E36*0.3)+(F36*0.5) -> 8.4961994 | H36: =(E36*0.2)+(F36*0.3)+(G36*0.5) -> 8.3244118 | I36: =(F36*0.2)+(G36*0.3)+(H36*0.5) -> 8.2572579
B37: Inventory Days | D37: =D35*365 -> 119.75508 | E37: =E35*365 -> 110.70198 | F37: =F35*365 -> 120.2165 | G37: =(D37*0.2)+(E37*0.3)+(F37*0.5) -> 117.26986 | H37: =(E37*0.2)+(F37*0.3)+(G37*0.5) -> 116.84028 | I37: =(F37*0.2)+(G37*0.3)+(H37*0.5) -> 117.64439
B38: Payable Days | D38: =(D50/D7)*365 -> 219.72744 | E38: =(E50/E7)*365 -> 222.16868 | F38: =(F50/F7)*365 -> 259.43095 | G38: =(D38*0.2)+(E38*0.3)+(F38*0.5) -> 240.31157 | H38: =(E38*0.2)+(F38*0.3)+(G38*0.5) -> 242.4188 | I38: =(F38*0.2)+(G38*0.3)+(H38*0.5) -> 245.18906
B39: Net Block % Revenue | D39: =D53/D6 -> 0.64936018 | E39: =E53/E6 -> 0.69054785 | F39: =F53/F6 -> 0.77499861 | G39: =(D39*0.2)+(E39*0.3)+(F39*0.5) -> 0.72453569 | H39: =(E39*0.2)+(F39*0.3)+(G39*0.5) -> 0.732877 | I39: =(F39*0.2)+(G39*0.3)+(H39*0.5) -> 0.73879893
B40: Debt % Revenue | D40: =D49/D6 -> 0.37998789 | E40: =E49/E6 -> 0.43378769 | F40: =F49/F6 -> 0.39795685 | G40: =(D40*0.2)+(E40*0.3)+(F40*0.5) -> 0.40511231 | H40: =(E40*0.2)+(F40*0.3)+(G40*0.5) -> 0.40870075 | I40: =(F40*0.2)+(G40*0.3)+(H40*0.5) -> 0.40547544
B41: CapEx | G41: 13000 | H41: =G41*1.05 -> 13650 | I41: =H41*1.05 -> 14332.5
B42: Other Liabilities % Revenue | D42: =D50/D6 -> 0.39356911 | E42: =E50/E6 -> 0.40947594 | F42: =F50/F6 -> 0.43924061 | G42: =(D42*0.2)+(E42*0.3)+(F42*0.5) -> 0.42117691 | H42: =(E42*0.2)+(F42*0.3)+(G42*0.5) -> 0.42425583 | I42: =(F42*0.2)+(G42*0.3)+(H42*0.5) -> 0.42632911
B43: Financial Liabilities % Revenue | D43: =D98/D6 -> -0.0049744562 | E43: =E98/E6 -> -0.0044430715 | F43: =F98/F6 -> -0.0050056014 | G43: =0 -> 0 | H43: =G43 -> 0 | I43: =H43 -> 0
B44: Other Financing Items % Revenue | D44: =D99/D6 -> 0.0017628774 | E44: =E99/E6 -> 0.0014276399 | F44: =F99/F6 -> 0.0012621697 | G44: =0 -> 0 | H44: =G44 -> 0 | I44: =H44 -> 0
...

Sheet WACC
B2: Weighted Average Cost Of Capital
B4: All Figures are in INR (Unless Stated)
B6: Peer Comps
H7: Debt / | I7: Debt/ | J7: Levered | K7: Unlevered
B8: Name of the Comp | D8: Country | E8: Total Debt | F8: Total Equity | G8: Tax Rate 1 | H8: Equity | I8: Capital | J8: Beta 2 | K8: Beta 3
B10: JSW Steel | D10: India | E10: =BETA_comps!G5 -> 99310 | F10: =BETA_comps!E5 -> 311708.35 | G10: 0.25 | H10: =E10/F10 -> 0.3185991 | I10: =E10/(F10+E10) -> 0.24161938 | J10: 0.937 | K10: =J10/(1+(1-G10)*H10) -> 0.75628598
B11: Tata Steel | D11: India | E11: =BETA_comps!G6 -> 92381.68 | F11: =BETA_comps!E6 -> 244528.39 | G11: 0.25 | H11: =E11/F11 -> 0.37779531 | I11: =E11/(F11+E11) -> 0.27420279 | J11: ='BETA-Regression'!L6 -> 1.1855027 | K11: =J11/(1+(1-G11)*H11) -> 0.92375887
B12: Jindal Steel | D12: India | E12: =BETA_comps!G7 -> 22609.55 | F12: =BETA_comps!E7 -> 116249.42 | G12: 0.25 | H12: =E12/F12 -> 0.19449172 | I12: =E12/(F12+E12) -> 0.16282383 | J12: 1.22 | K12: =J12/(1+(1-G12)*H12) -> 1.0646943
B13: S A I L | D13: India | E13: =BETA_comps!G8 -> 31927.71 | F13: =BETA_comps!E8 -> 74782.96 | G13: 0.25 | H13: =E13/F13 -> 0.4269383 | I13: =E13/(F13+E13) -> 0.29919885 | J13: 1.4 | K13: =J13/(1+(1-G13)*H13) -> 1.0604424
B14: Jindal Stain. | D14: India | E14: =BETA_comps!G9 -> 7460.33 | F14: =BETA_comps!E9 -> 58525.6 | G14: 0.25 | H14: =E14/F14 -> 0.12747123 | I14: =E14/(F14+E14) -> 0.11305941 | J14: 0.919 | K14: =J14/(1+(1-G14)*H14) -> 0.83880717
F16: Average | G16: =AVERAGE(G10:G14) -> 0.25 | H16: =AVERAGE(H10:H14) -> 0.28905913 | I16: =AVERAGE(I10:I14) -> 0.21818085 | J16: =AVERAGE(J10:J14) -> 1.1323005 | K16: =AVERAGE(K10:K14) -> 0.92879775
F17: Median | G17: =MEDIAN(G10:G14) -> 0.25 | H17: =MEDIAN(H10:H14) -> 0.3185991 | I17: =MEDIAN(I10:I14) -> 0.24161938 | J17: =MEDIAN(J10:J14) -> 1.1855027 | K17: =MEDIAN(K10:K14) -> 0.92375887
B19: Cost of Debt | G19: Cost of Debt
B21: Pre-Tax Cost of Debt | E21: =7167.06/92381.68 -> 0.077580966 | G21: Risk Free Rate | K21: 0.06866
B22: Tax Rate | E22: 0.25 | G22: Equity Risk Premium | K22: =RM!G8-WACC!K21 -> 0.082832308
B23: Post-Tax Cost of Debt | E23: =E21*(1-E22) -> 0.058185725 | G23: Levered Beta 4 | K23: =K31 -> 1.1444904
G24: Cost of Equity | K24: =K21+(K22*K23) -> 0.16346078
B26: Capital Structure | G26: Levered Beta
D28: Current | E28: Target | G28: Comps Median Unlevered Beta | K28: =K17 -> 0.92375887
B29: Total Debt | C29: =E11 -> 92381.68 | D29: =C29/$C$31 -> 0.27420279 | E29: =I17 -> 0.24161938 | G29: Target Debt / Equity | K29: =E33 -> 0.3185991
B30: Market Capitalization | C30: =F11 -> 244528.39 | D30: =C30/$C$31 -> 0.72579721 | E30: =E31-E29 -> 0.75838062 | G30: Tax Rate | K30: =E22 -> 0.25
B31: Total Capital | C31: =SUM(C29:C30) -> 336910.07 | D31: =C31/$C$31 -> 1 | E31: 1 | G31: Levered Beta | K31: =K28*(1+(1-K30)*K29) -> 1.1444904
B33: Debt / Equity | D33: =D29/D30 -> 0.37779531 | E33: =E29/E30 -> 0.3185991 | G33: Weighted Average Cost of Capital
G35: Cost Of Equity | K35: =K24 -> 0.16346078
B36: Notes: | G36: Equity Weight | K36: =E30 -> 0.75838062
B37: 1. Tax Rate Considered as Marginal Tax for the Country
B38: 2. Levered Beta is based on 5 year Monthly Data | G38: Cost Of Debt | K38: =E23 -> 0.058185725
B39: 3. Levered Beta = Unlevered beta/(1+(1-Tax rate)*Debt/Equity) | G39: Debt Weight | K39: =E29 -> 0.24161938
B40: 4. Unlevered Beta = Levered beta/(1+(1-Tax rate)*Debt/Equity)
G41: WACC | K41: =(K35*K36)+(K38*K39) -> 0.13802429

Sheet DATA>

Sheet BETA-Regression
B2: REGRESSION Beta - Tata Steel Ltd
B4: TATA STEEL MONTHLY RETURNS | G4: NIFTY MONTHLY RETURNS | K4: Beta Drifting
B5: Date | C5: Closing Return | D5: Weekly Return | G5: Date | H5: Closing Return | I5: Weekly Return
B6: 44378 | C6: 123.69 | G6: 44378 | H6: 15763.05 | K6: Levered Beta | L6: =O6 -> 1.1855027 | N6: BETA | O6: =P29 -> 1.1855027
B7: =EDATE(B6,1) -> 44409 | C7: 125.06 | D7: =C7/C6-1 -> 0.011076077 | G7: =EDATE(G6,1) -> 44409 | H7: 17132.2 | I7: =H7/H6-1 -> 0.086858191 | K7: Raw Beta Weight | L7: 0.75
B8: =EDATE(B7,1) -> 44440 | C8: 111.15 | D8: =C8/C7-1 -> -0.11122661 | G8: =EDATE(G7,1) -> 44440 | H8: 17618.15 | I8: =H8/H7-1 -> 0.028364717
B9: =EDATE(B8,1) -> 44470 | C9: 113.48 | D9: =C9/C8-1 -> 0.020962663 | G9: =EDATE(G8,1) -> 44470 | H9: 17671.65 | I9: =H9/H8-1 -> 0.0030366412 | K9: Mean/Marked Beta | L9: 1
B10: =EDATE(B9,1) -> 44501 | C10: 92.38 | D10: =C10/C9-1 -> -0.18593585 | G10: =EDATE(G9,1) -> 44501 | H10: 16983.2 | I10: =H10/H9-1 -> -0.038957879 | K10: Market Beta Weight | L10: 0.25
B11: =EDATE(B10,1) -> 44531 | C11: 95.85 | D11: =C11/C10-1 -> 0.037562243 | G11: =EDATE(G10,1) -> 44531 | H11: 17354.05 | I11: =H11/H10-1 -> 0.021836285
B12: =EDATE(B11,1) -> 44562 | C12: 93.61 | D12: =C12/C11-1 -> -0.023369849 | G12: =EDATE(G11,1) -> 44562 | H12: 17339.85 | I12: =H12/H11-1 -> -0.0008182528 | K12: Adjusted Beta | L12: =(L6*L7)+(L9*L10) -> 1.139127 | O12: SUMMARY OUTPUT
B13: =EDATE(B12,1) -> 44593 | C13: 105.27 | D13: =C13/C12-1 -> 0.12455934 | G13: =EDATE(G12,1) -> 44593 | H13: 16793.9 | I13: =H13/H12-1 -> -0.031485278
B14: =EDATE(B13,1) -> 44621 | C14: 112.73 | D14: =C14/C13-1 -> 0.070865394 | G14: =EDATE(G13,1) -> 44621 | H14: 17464.75 | I14: =H14/H13-1 -> 0.039946052 | O14: Regression Statistics
B15: =EDATE(B14,1) -> 44652 | C15: 109.61 | D15: =C15/C14-1 -> -0.02767675 | G15: =EDATE(G14,1) -> 44652 | H15: 17102.55 | I15: =H15/H14-1 -> -0.020738917 | O15: Multiple R | P15: 0.52279922
B16: =EDATE(B15,1) -> 44682 | C16: 91.03 | D16: =C16/C15-1 -> -0.16951008 | G16: =EDATE(G15,1) -> 44682 | H16: 16584.55 | I16: =H16/H15-1 -> -0.030287881 | O16: R Square | P16: 0.27331903
B17: =EDATE(B16,1) -> 44713 | C17: 74.77 | D17: =C17/C16-1 -> -0.17862243 | G17: =EDATE(G16,1) -> 44713 | H17: 15780.25 | I17: =H17/H16-1 -> -0.048496944 | O17: Adjusted R Square | P17: 0.26079004
B18: =EDATE(B17,1) -> 44743 | C18: 97.8 | D18: =C18/C17-1 -> 0.30801123 | G18: =EDATE(G17,1) -> 44743 | H18: 17158.25 | I18: =H18/H17-1 -> 0.087324345 | O18: Standard Error | P18: 0.076312042
B19: =EDATE(B18,1) -> 44774 | C19: 98.43 | D19: =C19/C18-1 -> 0.0064417178 | G19: =EDATE(G18,1) -> 44774 | H19: 17759.3 | I19: =H19/H18-1 -> 0.035029796 | O19: Observations | P19: 60
B20: =EDATE(B19,1) -> 44805 | C20: 90.25 | D20: =C20/C19-1 -> -0.083104744 | G20: =EDATE(G19,1) -> 44805 | H20: 17094.35 | I20: =H20/H19-1 -> -0.037442354
B21: =EDATE(B20,1) -> 44835 | C21: 92.3 | D21: =C21/C20-1 -> 0.022714681 | G21: =EDATE(G20,1) -> 44835 | H21: 18012.2 | I21: =H21/H20-1 -> 0.053693179 | O21: ANOVA
B22: =EDATE(B21,1) -> 44866 | C22: 97.84 | D22: =C22/C21-1 -> 0.060021668 | G22: =EDATE(G21,1) -> 44866 | H22: 18758.35 | I22: =H22/H21-1 -> 0.041424701 | P22: df | Q22: SS | R22: MS | S22: F | T22: Significance F
B23: =EDATE(B22,1) -> 44896 | C23: 102.39 | D23: =C23/C22-1 -> 0.046504497 | G23: =EDATE(G22,1) -> 44896 | H23: 18105.3 | I23: =H23/H22-1 -> -0.03481383 | O23: Regression | P23: 1 | Q23: 0.12703992 | R23: 0.12703992 | S23: 21.814942 | T23: 1.8258534e-05
B24: =EDATE(B23,1) -> 44927 | C24: 108.79 | D24: =C24/C23-1 -> 0.062506104 | G24: =EDATE(G23,1) -> 44927 | H24: 17662.15 | I24: =H24/H23-1 -> -0.024476258 | O24: Residual | P24: 58 | Q24: 0.33776461 | R24: 0.0058235278
B25: =EDATE(B24,1) -> 44958 | C25: 94.48 | D25: =C25/C24-1 -> -0.13153783 | G25: =EDATE(G24,1) -> 44958 | H25: 17303.95 | I25: =H25/H24-1 -> -0.020280657 | O25: Total | P25: 59 | Q25: 0.46480454
B26: =EDATE(B25,1) -> 44986 | C26: 94.98 | D26: =C26/C25-1 -> 0.0052921253 | G26: =EDATE(G25,1) -> 44986 | H26: 17359.75 | I26: =H26/H25-1 -> 0.0032246973
B27: =EDATE(B26,1) -> 45017 | C27: 98.11 | D27: =C27/C26-1 -> 0.032954306 | G27: =EDATE(G26,1) -> 45017 | H27: 18065 | I27: =H27/H26-1 -> 0.040625585 | P27: Coefficients | Q27: Standard Error | R27: t Stat | S27: P-value | T27: Lower 95% | U27: Upper 95% | V27: Lower 95.0% | W27: Upper 95.0%
B28: =EDATE(B27,1) -> 45047 | C28: 96.16 | D28: =C28/C27-1 -> -0.01987565 | G28: =EDATE(G27,1) -> 45047 | H28: 18534.4 | I28: =H28/H27-1 -> 0.025983947 | O28: Intercept | P28: 0.0023290291 | Q28: 0.010047641 | R28: 0.2317986 | S28: 0.81751033 | T28: -0.017783509 | U28: 0.022441568 | V28: -0.017783509 | W28: 0.022441568
B29: =EDATE(B28,1) -> 45078 | C29: 101.8 | D29: =C29/C28-1 -> 0.058652246 | G29: =EDATE(G28,1) -> 45078 | H29: 19189.05 | I29: =H29/H28-1 -> 0.035320809 | O29: X Variable 1 | P29: 1.1855027 | Q29: 0.25381981 | R29: 4.6706469 | S29: 1.8258534e-05 | T29: 0.67742715 | U29: 1.6935782 | V29: 0.67742715 | W29: 1.6935782
B30: =EDATE(B29,1) -> 45108 | C30: 115.58 | D30: =C30/C29-1 -> 0.13536346 | G30: =EDATE(G29,1) -> 45108 | H30: 19753.8 | I30: =H30/H29-1 -> 0.029430847
B31: =EDATE(B30,1) -> 45139 | C31: 115.35 | D31: =C31/C30-1 -> -0.0019899637 | G31: =EDATE(G30,1) -> 45139 | H31: 19253.8 | I31: =H31/H30-1 -> -0.025311586
B32: =EDATE(B31,1) -> 45170 | C32: 120.98 | D32: =C32/C31-1 -> 0.048807976 | G32: =EDATE(G31,1) -> 45170 | H32: 19638.3 | I32: =H32/H31-1 -> 0.019970084
B33: =EDATE(B32,1) -> 45200 | C33: 111.45 | D33: =C33/C32-1 -> -0.078773351 | G33: =EDATE(G32,1) -> 45200 | H33: 19079.6 | I33: =H33/H32-1 -> -0.028449509
B34: =EDATE(B33,1) -> 45231 | C34: 120.04 | D34: =C34/C33-1 -> 0.077074921 | G34: =EDATE(G33,1) -> 45231 | H34: 20133.15 | I34: =H34/H33-1 -> 0.055218663
B35: =EDATE(B34,1) -> 45261 | C35: 131.02 | D35: =C35/C34-1 -> 0.09146951 | G35: =EDATE(G34,1) -> 45261 | H35: 21731.4 | I35: =H35/H34-1 -> 0.079384001
B36: =EDATE(B35,1) -> 45292 | C36: 127.6 | D36: =C36/C35-1 -> -0.026102885 | G36: =EDATE(G35,1) -> 45292 | H36: 21725.7 | I36: =H36/H35-1 -> -0.00026229327
B37: =EDATE(B36,1) -> 45323 | C37: 132.2 | D37: =C37/C36-1 -> 0.036050157 | G37: =EDATE(G36,1) -> 45323 | H37: 21982.8 | I37: =H37/H36-1 -> 0.011833911
B38: =EDATE(B37,1) -> 45352 | C38: 146.27 | D38: =C38/C37-1 -> 0.10642965 | G38: =EDATE(G37,1) -> 45352 | H38: 22326.9 | I38: =H38/H37-1 -> 0.015653147
B39: =EDATE(B38,1) -> 45383 | C39: 154.86 | D39: =C39/C38-1 -> 0.058727012 | G39: =EDATE(G38,1) -> 45383 | H39: 22604.85 | I39: =H39/H38-1 -> 0.012449108
B40: =EDATE(B39,1) -> 45413 | C40: 156.93 | D40: =C40/C39-1 -> 0.013366912 | G40: =EDATE(G39,1) -> 45413 | H40: 22530.7 | I40: =H40/H39-1 -> -0.0032802695
B41: =EDATE(B40,1) -> 45444 | C41: 163.32 | D41: =C41/C40-1 -> 0.040718792 | G41: =EDATE(G40,1) -> 45444 | H41: 24010.6 | I41: =H41/H40-1 -> 0.065683712
... B65: =EDATE(B64,1) -> 46174 | C65: 193.29 | D65: =C65/C64-1 -> -0.051663232 | G65: =EDATE(G64,1) -> 46174 | H65: 23853.9 | I65: =H65/H64-1 -> 0.013001242
...

Sheet BETA_comps
B2: Comparison Beta
B4: S.No. | C4: Name | D4: CMP Rs. | E4: Mar Cap Rs.Cr. | F4: Debt / Eq | G4: Debt Rs.Cr.
B5: 1 | C5: JSW Steel | D5: 1274.3 | E5: 311708.35 | F5: 0.99 | G5: 99310
B6: 2 | C6: Tata Steel | D6: 196 | E6: 244528.39 | F6: 0.9 | G6: 92381.68
B7: 3 | C7: Jindal Steel | D7: 1139.8 | E7: 116249.42 | F7: 0.44 | G7: 22609.55
B8: 4 | C8: S A I L | D8: 180.99 | E8: 74782.96 | F8: 0.53 | G8: 31927.71
B9: 5 | C9: Jindal Stain. | D9: 709.85 | E9: 58525.6 | F9: 0.38 | G9: 7460.33

Sheet RM
B2: Return On Markets
B4: Year | C4: Annual
B5: 2000 | C5: -0.1465
B6: 2001 | C6: -0.1618 | E6: Average Return | G6: =AVERAGE(C5:C30) -> 0.15149231
B7: 2002 | C7: 0.0325 | E7: Dividend Yield | G7: 1.3% 1
B8: 2003 | C8: 0.719 | E8: Total Market Return | G8: =SUM(G6:G7) -> 0.15149231
B9: 2004 | C9: 0.1068
B10: 2005 | C10: 0.3634
B11: 2006 | C11: 0.3983
B12: 2007 | C12: 0.5477
B13: 2008 | C13: -0.5179
B14: 2009 | C14: 0.7576
B15: 2010 | C15: 0.1795
B16: 2011 | C16: -0.2462
B17: 2012 | C17: 0.277
B18: 2013 | C18: 0.0676
B19: 2014 | C19: 0.3139
B20: 2015 | C20: -0.0406
... B30: 2025 | C30: 0.1051
B31: 2026

Sheet Intrinsic Growth
B2: Calculation Of ROIC | G2: ='Raw FS'!J$3 -> 44621 | H2: ='Raw FS'!K$3 -> 44986 | I2: ='Raw FS'!L$3 -> 45352 | J2: ='Raw FS'!M$3 -> 45717 | K2: ='Raw FS'!N$3 -> 46082
B4: Current Assets
B5: ='Raw FS'!B38 -> Inventories | G5: ='Raw FS'!J38 -> 48824 | H5: ='Raw FS'!K38 -> 54415 | I5: ='Raw FS'!L38 -> 49158 | J5: ='Raw FS'!M38 -> 44590 | K5: ='Raw FS'!N38 -> 47249
B6: ='Raw FS'!B39 -> Trade receivables + | G6: ='Raw FS'!J39 -> 12246 | H6: ='Raw FS'!K39 -> 8257 | I6: ='Raw FS'!L39 -> 6264 | J6: ='Raw FS'!M39 -> 5260 | K6: ='Raw FS'!N39 -> 4917
B7: ='Raw FS'!B40 -> Cash Equivalents | G7: ='Raw FS'!J40 -> 15899 | H7: ='Raw FS'!K40 -> 13357 | I7: ='Raw FS'!L40 -> 8678 | J7: ='Raw FS'!M40 -> 11647 | K7: ='Raw FS'!N40 -> 10058
B8: ='Raw FS'!B41 -> Loans n Advances | G8: ='Raw FS'!J41 -> -158 | H8: ='Raw FS'!K41 -> -90 | I8: ='Raw FS'!L41 -> -56 | J8: ='Raw FS'!M41 -> 49 | K8: ='Raw FS'!N41 -> 1167
B9: ='Raw FS'!B42 -> Other asset items | G9: ='Raw FS'!J42 -> 37137 | H9: ='Raw FS'!K42 -> 23211 | I9: ='Raw FS'!L42 -> 15842 | J9: ='Raw FS'!M42 -> 15182 | K9: ='Raw FS'!N42 -> 17630
B10: Total Current Assets | G10: =SUM(G5:G9) -> 113948 | H10: =SUM(H5:H9) -> 99150 | I10: =SUM(I5:I9) -> 79886 | J10: =SUM(J5:J9) -> 76728 | K10: =SUM(K5:K9) -> 81021
B12: Current Liabilities
B13: ='Raw FS'!B15 -> Trade Payables | G13: ='Raw FS'!J15 -> 36765 | H13: ='Raw FS'!K15 -> 37833 | I13: ='Raw FS'!L15 -> 30228 | J13: ='Raw FS'!M15 -> 29314 | K13: ='Raw FS'!N15 -> 34810
B14: ='Raw FS'!B16 -> Advance from Customers | G14: ='Raw FS'!J16 -> 3253 | H14: ='Raw FS'!K16 -> 3394 | I14: ='Raw FS'!L16 -> 2771 | J14: ='Raw FS'!M16 -> 1655 | K14: ='Raw FS'!N16 -> 2222
B15: ='Raw FS'!B17 -> Other liability items | G15: ='Raw FS'!J17 -> 49744 | H15: ='Raw FS'!K17 -> 54101 | I15: ='Raw FS'!L17 -> 56799 | J15: ='Raw FS'!M17 -> 58335 | K15: ='Raw FS'!N17 -> 63320
B16: Total Current Liabilities | G16: =SUM(G13:G15) -> 89762 | H16: =SUM(H13:H15) -> 95328 | I16: =SUM(I13:I15) -> 89798 | J16: =SUM(J13:J15) -> 89304 | K16: =SUM(K13:K15) -> 100352
A18: # | B18: Net Working Capital | G18: =G10-G16 -> 24186 | H18: =H10-H16 -> 3822 | I18: =I10-I16 -> -9912 | J18: =J10-J16 -> -12576 | K18: =K10-K16 -> -19331
B20: Non-Current Assets
B21: ='Raw FS'!B21 -> Land | G21: ='Raw FS'!J21 -> 20770 | H21: ='Raw FS'!K21 -> 21701 | I21: ='Raw FS'!L21 -> 22067 | J21: ='Raw FS'!M21 -> 22299 | K21: ='Raw FS'!N21 -> 23659
B22: ='Raw FS'!B22 -> Building | G22: ='Raw FS'!J22 -> 27588 | H22: ='Raw FS'!K22 -> 28904 | I22: ='Raw FS'!L22 -> 30173 | J22: ='Raw FS'!M22 -> 31819 | K22: ='Raw FS'!N22 -> 36997
B23: ='Raw FS'!B23 -> Plant Machinery | G23: ='Raw FS'!J23 -> 152754 | H23: ='Raw FS'!K23 -> 163134 | I23: ='Raw FS'!L23 -> 175111 | J23: ='Raw FS'!M23 -> 186115 | K23: ='Raw FS'!N23 -> 224912
B24: ='Raw FS'!B24 -> Equipments | G24: ='Raw FS'!J24 -> 0 | H24: ='Raw FS'!K24 -> 0 | I24: ='Raw FS'!L24 -> 0 | J24: ='Raw FS'!M24 -> 0 | K24: ='Raw FS'!N24 -> 0
B25: ='Raw FS'!B25 -> Furniture n fittings | G25: ='Raw FS'!J25 -> 991 | H25: ='Raw FS'!K25 -> 1111 | I25: ='Raw FS'!L25 -> 1238 | J25: ='Raw FS'!M25 -> 1298 | K25: ='Raw FS'!N25 -> 1429
B26: ='Raw FS'!B26 -> Railway sidings | G26: ='Raw FS'!J26 -> 1780 | H26: ='Raw FS'!K26 -> 1841 | I26: ='Raw FS'!L26 -> 1872 | J26: ='Raw FS'!M26 -> 1890 | K26: ='Raw FS'!N26 -> 2384
B27: ='Raw FS'!B27 -> Vehicles | G27: ='Raw FS'!J27 -> 686 | H27: ='Raw FS'!K27 -> 749 | I27: ='Raw FS'!L27 -> 794 | J27: ='Raw FS'!M27 -> 830 | K27: ='Raw FS'!N27 -> 978
B28: ='Raw FS'!B28 -> Intangible Assets | G28: ='Raw FS'!J28 -> 6229 | H28: ='Raw FS'!K28 -> 7572 | I28: ='Raw FS'!L28 -> 7772 | J28: ='Raw FS'!M28 -> 7896 | K28: ='Raw FS'!N28 -> 10230
B29: ='Raw FS'!B29 -> Other fixed assets | G29: ='Raw FS'!J29 -> 10953 | H29: ='Raw FS'!K29 -> 20384 | I29: ='Raw FS'!L29 -> 20546 | J29: ='Raw FS'!M29 -> 20881 | K29: ='Raw FS'!N29 -> 22389
B30: Gross Block | G30: =SUM(G21:G29) -> 221751 | H30: =SUM(H21:H29) -> 245396 | I30: =SUM(I21:I29) -> 259573 | J30: =SUM(J21:J29) -> 273028 | K30: =SUM(K21:K29) -> 322978
B31: Accumulated Depreciation | G31: =-'Raw FS'!J31 -> -88464 | H31: =-'Raw FS'!K31 -> -98773 | I31: =-'Raw FS'!L31 -> -110758 | J31: =-'Raw FS'!M31 -> -122114 | K31: =-'Raw FS'!N31 -> -143070
B32: Net Non-Current Assets | G32: =SUM(G30:G31) -> 133287 | H32: =SUM(H30:H31) -> 146623 | I32: =SUM(I30:I31) -> 148815 | J32: =SUM(J30:J31) -> 150914 | K32: =SUM(K30:K31) -> 179908
A34: # | B34: Invested Capital | G34: =G32+G18 -> 157473 | H34: =H32+H18 -> 150445 | I34: =I32+I18 -> 138903 | J34: =J32+J18 -> 138338 | K34: =K32+K18 -> 160577
B35: EBIT | G35: ='Data Sheet'!G28+'Data Sheet'!G27 -> 55689.07 | H35: ='Data Sheet'!H28+'Data Sheet'!H27 -> 24533.82 | I35: ='Data Sheet'!I28+'Data Sheet'!I27 -> 6360.53 | J35: ='Data Sheet'!J28+'Data Sheet'!J27 -> 15753.82 | K35: ='Data Sheet'!K28+'Data Sheet'!K27 -> 23135.75
A37: # | B37: Return On Invested Capital | G37: =G35/G34 -> 0.35364202 | H37: =H35/H34 -> 0.16307501 | I37: =I35/I34 -> 0.045791164 | J37: =J35/J34 -> 0.11387919 | K37: =K35/K34 -> 0.14407885
B40: Calculation Of Reinvested Rates | G40: ='Raw FS'!J$3 -> 44621 | H40: ='Raw FS'!K$3 -> 44986 | I40: ='Raw FS'!L$3 -> 45352 | J40: ='Raw FS'!M$3 -> 45717 | K40: ='Raw FS'!N$3 -> 46082
B42: Net CapEx | G42: =-SUM('Raw FS'!J59:J60) -> 9953 | H42: =-SUM('Raw FS'!K59:K60) -> 13814 | I42: =-SUM('Raw FS'!L59:L60) -> 17732 | J42: =-SUM('Raw FS'!M59:M60) -> 14407 | K42: =-SUM('Raw FS'!N59:N60) -> 13158
B43: Change In working capital | H43: =H18-G18 -> -20364 | I43: =I18-H18 -> -13734 | J43: =J18-I18 -> -2664 | K43: =K18-J18 -> -6755
B45: EBIT | G45: =G35 -> 55689.07 | H45: =H35 -> 24533.82 | I45: =I35 -> 6360.53 | J45: =J35 -> 15753.82 | K45: =K35 -> 23135.75
B46: Marginal Tax Rate | G46: 0.25 | H46: 0.25 | I46: 0.25 | J46: 0.25 | K46: 0.25
B47: EBIT(1-T) | G47: =G45*(1-G46) -> 41766.802 | H47: =H45*(1-H46) -> 18400.365 | I47: =I45*(1-I46) -> 4770.3975 | J47: =J45*(1-J46) -> 11815.365 | K47: =K45*(1-K46) -> 17351.812
B49: Reinvestment | H49: =SUM(H42:H43) -> -6550 | I49: =SUM(I42:I43) -> 3998 | J49: =SUM(J42:J43) -> 11743 | K49: =SUM(K42:K43) -> 6403
B51: Reinvestment Rate | H51: =H49/H47 -> -0.3559712 | I51: =I49/I47 -> 0.8380853 | J51: =J49/J47 -> 0.99387535 | K51: =K49/K47 -> 0.36901044
I53: 4 Year Average | K53: =AVERAGE(H51:K51) -> 0.46124997
I54: 4 Year Median | K54: =MEDIAN(H51:K51) -> 0.60354787
...

Sheet DCF
B2: Calculation Of PV of FCFF | F2: ='Intrinsic Growth'!K2 -> 46082 | G2: =F2+365 -> 46447 | H2: =G2+366 -> 46813 | I2: =H2+365 -> 47178 | J2: =I2+365 -> 47543 | K2: =J2+365 -> 47908
B4: EBIT | F4: =FM!F14 -> 24377.17 | G4: =F4*(1+$D$15) -> 25474.143 | H4: =G4*(1+$D$15) -> 26620.479 | I4: =H4*(1+$D$15) -> 27818.401 | J4: =I4*(1+$D$15) -> 29070.229 | K4: =J4*(1+$D$15) -> 30378.389
B5: TAX RATE | F5: 0.25 | G5: 0.25 | H5: 0.25 | I5: 0.25 | J5: 0.25 | K5: 0.25
B6: EBIT(1-TAX) | F6: =F4*(1-F5) -> 18282.878 | G6: =G4*(1-G5) -> 19105.607 | H6: =H4*(1-H5) -> 19965.359 | I6: =I4*(1-I5) -> 20863.8 | J6: =J4*(1-J5) -> 21802.671 | K6: =K4*(1-K5) -> 22783.792
B7: Less: Reinvestment Rate | F7: ='Intrinsic Growth'!K54 -> 0.60354787 | G7: =F7 -> 0.60354787 | H7: =G7 -> 0.60354787 | I7: =H7 -> 0.60354787 | J7: =I7 -> 0.60354787 | K7: =J7 -> 0.60354787
B8: Free Cash Flow From Firm(FCFF) | F8: =F6*(1-F7) -> 7248.2857 | G8: =G6*(1-G7) -> 7574.4586 | H8: =H6*(1-H7) -> 7915.3092 | I8: =I6*(1-I7) -> 8271.4982 | J8: =J6*(1-J7) -> 8643.7156 | K8: =K6*(1-K7) -> 9032.6828
B9: Mid Year Convention | G9: 0.5 | H9: =G9+1 -> 1.5 | I9: =H9+1 -> 2.5 | J9: =I9+1 -> 3.5 | K9: =J9+1 -> 4.5
B10: Discounting Factor | G10: =1/(1+$D$16)^G9 -> 0.93739846 | H10: =1/(1+$D$16)^H9 -> 0.8237069 | I10: =1/(1+$D$16)^I9 -> 0.72380432 | J10: =1/(1+$D$16)^J9 -> 0.63601834 | K10: =1/(1+$D$16)^K9 -> 0.55887941
B12: PV of FCFF | G12: =G8*G10 -> 7100.2858 | H12: =H8*H10 -> 6519.8948 | I12: =I8*I10 -> 5986.9461 | J12: =J8*J10 -> 5497.5617 | K12: =K8*K10 -> 5048.1804
B14: Expected Growth | D14: ='Intrinsic Growth'!K64 -> 0.045771751
B15: Terminal Growth | D15: 0.045
B16: WACC | D16: =WACC!K41 -> 0.13802429
B18: Calculation Of Terminal Value | F18: SENSITIVITY ANALYSIS
F19: =D30 -> 86862.236 | G19: 0.1 | H19: =D21 -> 0.13802429 | I19: 0.15 | J19: 0.18
B20: FCFF(n+1) | D20: =K8*(1+D15) -> 9439.1535 | F20: 0.03 | G20: 105514.99 | H20: =G8/(1+H$19)^0.5+H8/(1+H$19)^1.5+I8/(1+H$19)^2.5+J8/(1+H$19)^3.5+K8/(1+H$19)^4.5+K8*(1+$F20)/(H$19-$F20)/(1+H$19)^4.5 -> 78286.728 | I20: 74114.107 | J20: 65321.859
B21: WACC | D21: =D16 -> 0.13802429 | F21: 0.045 | G21: 118075.34 | H21: =G8/(1+H$19)^0.5+H8/(1+H$19)^1.5+I8/(1+H$19)^2.5+J8/(1+H$19)^3.5+K8/(1+H$19)^4.5+K8*(1+$F21)/(H$19-$F21)/(1+H$19)^4.5 -> 86862.236 | I21: 78110.583 | J21: 67833.93
B22: Terminal Growth Rate | D22: =D15 -> 0.045 | F22: 0.05 | G22: 135659.84 | H22: =G8/(1+H$19)^0.5+H8/(1+H$19)^1.5+I8/(1+H$19)^2.5+J8/(1+H$19)^3.5+K8/(1+H$19)^4.5+K8*(1+$F22)/(H$19-$F22)/(1+H$19)^4.5 -> 90370.22 | I22: 82906.354 | J22: 70732.473
F23: 0.06 | G23: 180877.11 | H23: =G8/(1+H$19)^0.5+H8/(1+H$19)^1.5+I8/(1+H$19)^2.5+J8/(1+H$19)^3.5+K8/(1+H$19)^4.5+K8*(1+$F23)/(H$19-$F23)/(1+H$19)^4.5 -> 98734.991 | I23: 92215.793 | J23: 76025.465
B24: Terminal Value | D24: =D20/(D21-D22) -> 101469.77 | F24: 0.07 | G24: 205997.82 | H24: =G8/(1+H$19)^0.5+H8/(1+H$19)^1.5+I8/(1+H$19)^2.5+J8/(1+H$19)^3.5+K8/(1+H$19)^4.5+K8*(1+$F24)/(H$19-$F24)/(1+H$19)^4.5 -> 109559.11 | I24: 96094.726 | J24: 78110.583
B26: Calculation Of Equity Value Per Share
B28: PV of FCFF | D28: =SUM(G12:K12) -> 30152.869
B29: PV of Terminal Value | D29: =D24*K10 -> 56709.367
B30: Value of Operating Assets | D30: =SUM(D28:D29) -> 86862.236
B32: Add: CASH | D32: ='Data Sheet'!K69 -> 10057.53
B33: Less: Debt | D33: ='Raw FS'!N8+'Raw FS'!N9 -> 84957 | E33: Note: LT + ST Borrowings only; excl. lease liabilities (₹7,425 Cr)
B34: Value Of Equity | D34: =D30+D32-D33 -> 11962.766
B35: No. Of Shares | D35: ='Data Sheet'!B6 -> 1247.5527
B37: Equity Value Per Share | D37: =D34/D35 -> 9.5889863
B39: Share Price | D39: 196
B40: Discount/Premium | D40: =D39/D37 -> 20.440117

Sheet DATA ROOM>

Sheet Data Sheet
A1: COMPANY NAME | B1: TATA STEEL LTD | E1: =IF(B2<>B3, "A NEW VERSION OF THE WORKSHEET IS AVAILABLE", "")
A2: LATEST VERSION | B2: 2.1 | E2: PLEASE DO NOT MAKE ANY CHANGES TO THIS SHEET
A3: CURRENT VERSION | B3: 2.1
A5: META
A6: Number of shares | B6: =IF(B9>0, B9/B8, 0) -> 1247.5527
A7: Face Value | B7: 1
A8: Current Price | B8: 201.25
A9: Market Capitalization | B9: 251069.99
A15: PROFIT & LOSS
A16: Report Date | B16: 42825 | C16: 43190 | D16: 43555 | E16: 43921 | F16: 44286 | G16: 44651 | H16: 45016 | I16: 45382 | J16: 45747 | K16: 46112
A17: Sales | B17: 112299.42 | C17: 123249.07 | D17: 157668.99 | E17: 139816.65 | F17: 156477.4 | G17: 243959.17 | H17: 243352.69 | I17: 229170.78 | J17: 218542.51 | K17: 232139.94
A18: Raw Material Cost | B18: 43843.03 | C18: 46137.01 | D18: 60877.05 | E18: 58039.99 | F18: 55100.81 | G18: 91076.61 | H18: 116597.19 | I18: 97506.39 | J18: 95097.3 | K18: 92628.07
A19: Change in Inventory | B19: 4538.13 | C19: -99.31 | D19: 96.71 | E19: 565.24 | F19: -1516.77 | G19: 7597.87 | H19: 3358.89 | I19: -4409.35 | J19: 96.65 | K19: -989.62
A20: Power and Fuel | B20: 5220.83 | C20: 4440.43 | D20: 5316.56 | E20: 5319.92 | F20: 5708.42 | G20: 8028.29 | H20: 9526.91 | I20: 16612.61 | J20: 13124.85 | K20: 14333.15
A21: Other Mfr. Exp | B21: 15799.14 | C21: 16955.79 | D21: 20734.28 | E21: 21232.69 | F21: 20744.93 | G21: 28834.06 | H21: 33144.83 | I21: 40116.91 | J21: 38700.5 | K21: 37485.96
A22: Employee Cost | B22: 17252.22 | C22: 17077.51 | D22: 18758.87 | E22: 18533.58 | F22: 19908.81 | G22: 23264.1 | H22: 22419.32 | I22: 24509.58 | J22: 24888.99 | K22: 25998.98
A23: Selling and admin | B23: 13772.32 | C23: 14423.87 | D23: 16917.14 | E23: 15599.07 | F23: 17509.77 | G23: 27445.67 | H23: 25519.92 | I23: 14453.57 | J23: 12137.26 | K23: 13348.99
A24: Other Expenses | B24: 7806.38 | C24: 2681.96 | D24: 5843.58 | E24: 4193.58 | F24: 5483.63 | G24: 9418.36 | H24: 7203.25 | I24: 9314.45 | J24: 9391.81 | K24: 13002.73
A25: Other Income | B25: -3789.11 | C25: 10898.41 | D25: 1524.31 | E25: -2883.63 | F25: 179.78 | G25: 1299.99 | H25: 1568.86 | I25: -6005.23 | J25: 876.7 | K25: 737.82
A26: Depreciation | B26: 5672.88 | C26: 5741.7 | D26: 7341.83 | E26: 8440.73 | F26: 9233.64 | G26: 9100.87 | H26: 9335.2 | I26: 9882.16 | J26: 10421.33 | K26: 11954.51
A27: Interest | B27: 5072.2 | C27: 5454.74 | D27: 7660.1 | E27: 7533.46 | F27: 7606.71 | G27: 5462.2 | H27: 6298.7 | I27: 7507.57 | J27: 7340.95 | K27: 7167.06
... A31: Dividend Amount | B31: 970.24 | C31: 1144.95 | D31: 1488.42 | E31: 1144.95 | F31: 2994.02 | G31: 6228.17 | H31: 4396.46 | I31: 4490.78 | J31: 4490.78 | K31: 4989.76
A40: Quarters
A41: Report Date | B41: 45291 | C41: 45382 | D41: 45473 | E41: 45565 | F41: 45657 | G41: 45747 | H41: 45838 | I41: 45930 | J41: 46022 | K41: 46112
A42: Sales | B42: 55311.88 | C42: 58687.31 | D42: 54771.39 | E42: 53904.71 | F42: 53648.3 | G42: 56218.11 | H42: 53178.12 | I42: 58689.29 | J42: 57002.4 | K42: 63270.13
A43: Expenses | B43: 49048.31 | C43: 52086.68 | D43: 48076.92 | E43: 47788.92 | F43: 47744.81 | G43: 49658.89 | H43: 45750.58 | I43: 49792.75 | J43: 48802.7 | K43: 53441.47
A44: Other Income | B44: -32.84 | C44: -381.56 | D44: -5.51 | E44: 616.68 | F44: 141.82 | G44: 149.19 | H44: 236.27 | I44: -6.11 | J44: 465.17 | K44: 42.49
A45: Depreciation | B45: 2422.04 | C45: 2567.95 | D45: 2535.43 | E45: 2596.74 | F45: 2569.19 | G45: 2719.97 | H45: 2744.3 | I45: 2893 | J45: 3048.81 | K45: 3268.4
A46: Interest | B46: 1880.78 | C46: 1842.25 | D46: 1776.71 | E46: 1971.4 | F46: 1804.09 | G46: 1788.75 | H46: 1852.43 | I46: 1774.96 | J46: 1747.29 | K46: 1792.38
A47: Profit before tax | B47: 1927.91 | C47: 1808.87 | D47: 2376.82 | E47: 2164.33 | F47: 1672.03 | G47: 2199.69 | H47: 3067.08 | I47: 4222.47 | J47: 3868.77 | K47: 4810.37
A48: Tax | B48: 1405.77 | C48: 1254.31 | D48: 1458.25 | E48: 1405.49 | F48: 1376.54 | G48: 998.81 | H48: 1059.72 | I48: 1039.38 | J48: 1138.4 | K48: 1845.37
A49: Net profit | B49: 513.37 | C49: 611.48 | D49: 959.61 | E49: 833.45 | F49: 326.64 | G49: 1300.81 | H49: 2077.68 | I49: 3101.75 | J49: 2688.7 | K49: 2925.74
A50: Operating Profit | B50: 6263.57 | C50: 6600.63 | D50: 6694.47 | E50: 6115.79 | F50: 5903.49 | G50: 6559.22 | H50: 7427.54 | I50: 8896.54 | J50: 8199.7 | K50: 9828.66
A55: BALANCE SHEET
A56: Report Date | B56: 42825 | C56: 43190 | D56: 43555 | E56: 43921 | F56: 44286 | G56: 44651 | H56: 45016 | I56: 45382 | J56: 45747 | K56: 46112
A57: Equity Share Capital | B57: 970.24 | C57: 1144.95 | D57: 1144.94 | E57: 1144.95 | F57: 1197.61 | G57: 1221.21 | H57: 1221.24 | I57: 1247.44 | J57: 1247.44 | K57: 1247.44
A58: Reserves | B58: 36849.08 | C58: 59725.67 | D58: 67780.14 | E58: 72431.35 | F58: 73041.16 | G58: 113221.83 | H58: 101860.86 | I58: 90788.32 | J58: 89922.19 | K58: 100920.21
A59: Borrowings | B59: 83014.49 | C59: 92147.05 | D59: 100816.22 | E59: 116328.2 | F59: 88501.41 | G59: 75561.35 | H59: 84893.05 | I59: 87082.12 | J59: 94801.05 | K59: 92381.68
